05:45:28 PM:DEBUG [Logger_base.py:15] mensaje a nivel debug
05:45:28 PM:INFO [Logger_base.py:16] mensaje a nivel info
05:45:28 PM:WARNING [Logger_base.py:17] mensaje a nivel warning
05:45:28 PM:ERROR [Logger_base.py:18] mensaje a nivel error
05:45:28 PM:CRITICAL [Logger_base.py:19] mensaje a nivel critical
05:37:45 PM:DEBUG [Persona.py:52] 
            Id Persona: 1,
            Nombre: Juan,
            Apellido: Perez,
        
05:39:30 PM:DEBUG [Persona.py:52] 
            Id Persona: 1,
            Nombre: Juan,
            Apellido: Perez,
        
05:41:14 PM:DEBUG [Persona.py:52] 
            Id Persona: 1,
            Nombre: Juan,
            Apellido: Perez,
        
05:41:14 PM:DEBUG [Persona.py:54] 
            Id Persona: None,
            Nombre: Jose,
            Apellido: Lepez,
        
05:44:18 PM:DEBUG [Persona.py:53] 
            Id Persona: 1,
            Nombre: Juan,
            Apellido: Perez,
            Email: jperez@mail..com
        
05:44:18 PM:DEBUG [Persona.py:55] 
            Id Persona: None,
            Nombre: Jose,
            Apellido: Lepez,
            Email: ljose@mail.com
        
05:45:31 PM:DEBUG [Persona.py:53] 
            Id Persona: 1,
            Nombre: Juan,
            Apellido: Perez,
            Email: jperez@mail..com
        
05:45:31 PM:DEBUG [Persona.py:55] 
            Id Persona: None,
            Nombre: Jose,
            Apellido: Lepez,
            Email: ljose@mail.com
        
05:45:31 PM:DEBUG [Persona.py:57] 
            Id Persona: 1,
            Nombre: None,
            Apellido: None,
            Email: None
        
07:03:50 PM:DEBUG [conexion.py:23] Conexion  Exitosa: <connection object at 0x000002190F3BE370; dsn: 'user=postgres password=xxx dbname=test_bd host=127.0.0.1 port=5432', closed: 0>
07:03:50 PM:ERROR [conexion.py:40] Ocurrio un error: 'NoneType' object has no attribute 'cursor'
07:17:16 PM:ERROR [conexion.py:26] Ocurrio un error:connection to server at "127.0.0.1", port 5432 failed: FATAL:  password authentication failed for user "postgre"

07:17:40 PM:DEBUG [conexion.py:23] Conexion  Exitosa: <connection object at 0x000001BC04DAC370; dsn: 'user=postgres password=xxx dbname=test_bd host=127.0.0.1 port=5432', closed: 0>
07:18:28 PM:DEBUG [conexion.py:23] Conexion  Exitosa: <connection object at 0x000002013D9BC370; dsn: 'user=postgres password=xxx dbname=test_bd host=127.0.0.1 port=5432', closed: 0>
07:18:28 PM:ERROR [conexion.py:53] Ocurrio un error: 'NoneType' object has no attribute 'cursor'
07:21:13 PM:DEBUG [conexion.py:23] Conexion  Exitosa: <connection object at 0x0000016055BDC370; dsn: 'user=postgres password=xxx dbname=test_bd host=127.0.0.1 port=5432', closed: 0>
07:21:13 PM:ERROR [conexion.py:53] Ocurrio un error: 'NoneType' object has no attribute 'cursor'
07:22:05 PM:DEBUG [conexion.py:23] Conexion  Exitosa: <connection object at 0x000001F808DAC370; dsn: 'user=postgres password=xxx dbname=test_bd host=127.0.0.1 port=5432', closed: 0>
07:22:05 PM:DEBUG [conexion.py:50] Se abrio correctamente el cursor : <cursor object at 0x000001F808FE1820; closed: 0>
